<?xml version="1.0"?>
<robot xmlns:xacro="http://www.ros.org/wiki/xacro" name="my_robot">

    <!-- Materials -->
    <xacro:include filename="$(find robot_description)/urdf/my_materials.xacro" />

    <!-- BASE LINK -->

    <link name="base_link">
    </link>

    <!-- Box -->
    <link name="box">
        <visual>
            <origin xyz="0.15 0 0.075"/>
            <geometry>
                <box size="0.3 0.3 0.15"/>
            </geometry>
            <material name="blue"/>
        </visual>
        <collision>
            <origin xyz="0.15 0 0.075"/>
            <geometry>
                <box size="0.3 0.3 0.15"/>
            </geometry>
        </collision>
        <inertial>
            <mass value="1.0"/>
            <origin xyz="0 0 0" rpy="0 0 0"/>
            <inertia ixx="0.009375" ixy="0.0" ixz="0.0" iyy="0.009375" iyz="0.0" izz="0.015"/>
        </inertial>
    </link>

    <joint name="box_joint" type="fixed">
        <parent link="base_link"/>
        <child link="box"/>
        <origin xyz="-0.1 0 0"/>
    </joint>
   
    <!-- Left Wheel -->
    <link name="left_wheel">
        <visual>
            <geometry>
                <cylinder radius="0.05" length="0.04"/>
            </geometry>
            <material name="orange"/>
        </visual>
        <collision>
            <geometry>
                <cylinder radius="0.05" length="0.04"/>
            </geometry>
        </collision>
        <inertial>
            <mass value="0.5"/>
            <origin xyz="0 0 0" rpy="0 0 0"/>
            <inertia ixx="0.00037917" ixy="0.0" ixz="0.0" iyy="0.00037917" iyz="0.0" izz="0.000625"/>
        </inertial>
    </link>

    <joint name="left_wheel_joint" type="continuous">
        <parent link="base_link"/>
        <child link="left_wheel"/>
        <origin xyz="0 0.175 0" rpy="-${pi/2} 0 0" />
        <axis xyz="0 0 1"/>
        <dynamics damping="0.3" friction="0.4"/>
    </joint>

    <!-- Right Wheel -->
    <link name="right_wheel">
        <visual>
            <geometry>
                <cylinder radius="0.05" length="0.04"/>
            </geometry>
            <material name="orange"/>
        </visual>
        <collision>
            <geometry>
                <cylinder radius="0.05" length="0.04"/>
            </geometry>
        </collision>
        <inertial>
            <mass value="0.5"/>
            <origin xyz="0 0 0" rpy="0 0 0"/>
            <inertia ixx="0.00037917" ixy="0.0" ixz="0.0" iyy="0.00037917" iyz="0.0" izz="0.000625"/>
        </inertial>
    </link>

    <joint name="right_wheel_joint" type="continuous">
        <parent link="base_link"/>
        <child link="right_wheel"/>
        <origin xyz="0 -0.175 0" rpy="${pi/2} 0 0" />
        <axis xyz="0 0 -1"/>
        <dynamics damping="0.3" friction="0.4"/>
    </joint>

    <!-- Caster Wheel -->
    <link name="caster_wheel">
        <visual>
            <geometry>
                <sphere radius="0.05"/>
            </geometry>
            <material name="orange"/>
        </visual>
        <collision>
            <geometry>
                <sphere radius="0.05"/>
            </geometry>
        </collision>
        <inertial>
            <mass value="1.5"/>
            <origin xyz="0 0 0" rpy="0 0 0"/>
            <inertia ixx="0.0015" ixy="0.0" ixz="0.0" iyy="0.0015" iyz="0.0" izz="0.0015"/>
        </inertial>
    </link>

    <joint name="caster_wheel_joint" type="fixed">
        <parent link="base_link"/>
        <child link="caster_wheel"/>
        <origin xyz="0.125 0 0"/>
    </joint>

    <!-- Plate -->
    <link name="plate">
        <visual>
            <geometry>
                <cylinder radius="0.1" length="0.05"/>
            </geometry>
            <origin xyz="0 0 0" rpy="0 0 0"/>
            <material name="green"/>
        </visual>
        <collision>
            <geometry>
                <cylinder radius="0.1" length="0.05"/>
            </geometry>
        </collision>
        <inertial>
            <mass value="0.02"/>
            <origin xyz="0 0 0" rpy="0 0 0"/>
            <inertia ixx="0.01" ixy="0.0" ixz="0.0" iyy="0.01" iyz="0.0" izz="0.01"/>
        </inertial>
    </link>

    <joint name="plate_joint" type="fixed">
        <parent link="box"/>
        <child link="plate"/>
        <origin xyz="0.15 0 0.15" rpy="0 0 0"/>
    </joint>

    <!-- Camera -->
    <xacro:include filename="$(find robot_description)/urdf/my_camera.xacro" />
    <xacro:camera_sensor parent_link="plate" camera_name="camera" origin_xyz="0 0 0.075" origin_rpy="0 0 0" />

    <!-- Gazebo -->
    <xacro:include filename="$(find robot_description)/urdf/my_gazebo.xacro" />

</robot>
